Script started on 2021-09-08 23:18:29+00:00 [TERM="screen" TTY="/dev/pts/0" COLUMNS="318" LINES="79"]
Initialize s3
Testing write data of size 4
Expected write size 4, input data size: 4
./^CTraceback (most recent call last):
  File "benchmark.py", line 165, in <module>
    results, write_capacity = test_s3_write(client, f"size_{size}", size, args.repetitions)
  File "benchmark.py", line 58, in test_s3_write
    client.put_object(Bucket=S3_BUCKET_NAME, Key=name, Body=data)
  File "/home/ubuntu/data/python-venv/lib/python3.8/site-packages/botocore/client.py", line 276, in _api_call
    return self._make_api_call(operation_name, kwargs)
  File "/home/ubuntu/data/python-venv/lib/python3.8/site-packages/botocore/client.py", line 572, in _make_api_call
    http, parsed_response = self._make_request(
  File "/home/ubuntu/data/python-venv/lib/python3.8/site-packages/botocore/client.py", line 592, in _make_request
    return self._endpoint.make_request(operation_model, request_dict)
  File "/home/ubuntu/data/python-venv/lib/python3.8/site-packages/botocore/endpoint.py", line 102, in make_request
    return self._send_request(request_dict, operation_model)
  File "/home/ubuntu/data/python-venv/lib/python3.8/site-packages/botocore/endpoint.py", line 134, in _send_request
    success_response, exception = self._get_response(
  File "/home/ubuntu/data/python-venv/lib/python3.8/site-packages/botocore/endpoint.py", line 166, in _get_response
    success_response, exception = self._do_get_response(
  File "/home/ubuntu/data/python-venv/lib/python3.8/site-packages/botocore/endpoint.py", line 200, in _do_get_response
    http_response = self._send(request)
  File "/home/ubuntu/data/python-venv/lib/python3.8/site-packages/botocore/endpoint.py", line 244, in _send
    return self.http_session.send(request)
  File "/home/ubuntu/data/python-venv/lib/python3.8/site-packages/botocore/httpsession.py", line 254, in send
    urllib_response = conn.urlopen(
  File "/home/ubuntu/data/python-venv/lib/python3.8/site-packages/urllib3/connectionpool.py", line 670, in urlopen
    httplib_response = self._make_request(
  File "/home/ubuntu/data/python-venv/lib/python3.8/site-packages/urllib3/connectionpool.py", line 426, in _make_request
    six.raise_from(e, None)
  File "<string>", line 3, in raise_from
  File "/home/ubuntu/data/python-venv/lib/python3.8/site-packages/urllib3/connectionpool.py", line 421, in _make_request
    httplib_response = conn.getresponse()
  File "/usr/lib/python3.8/http/client.py", line 1344, in getresponse
    response.begin()
  File "/usr/lib/python3.8/http/client.py", line 307, in begin
    version, status, reason = self._read_status()
  File "/usr/lib/python3.8/http/client.py", line 268, in _read_status
    line = str(self.fp.readline(_MAXLINE + 1), "iso-8859-1")
  File "/usr/lib/python3.8/socket.py", line 655, in readinto
    def readinto(self, b):
KeyboardInterrupt

Script done on 2021-09-08 23:18:31+00:00 [COMMAND_EXIT_CODE="130"]
