Script started on 2021-09-15 16:39:34+00:00 [TERM="xterm-256color" TTY="/dev/pts/1" COLUMNS="238" LINES="60"]
Update config to 128
Connected ecc231cf
Execute size 524288
Traceback (most recent call last):
  File "benchmark.py", line 62, in <module>
    client.create(f"/size_{size}", data)
  File "/home/ubuntu/data/python-venv/lib/python3.8/site-packages/faaskeeper/client.py", line 195, in create
    return self.create_async(path, value, ephemeral, sequential).get()
  File "/home/ubuntu/data/python-venv/lib/python3.8/site-packages/faaskeeper/threading.py", line 26, in get
    raise self._exception
faaskeeper.exceptions.FaaSKeeperException: unknown error

Script done on 2021-09-15 16:39:37+00:00 [COMMAND_EXIT_CODE="0"]
